#VRML_SIM R2023b utf8

EXTERNPROTO "https://raw.githubusercontent.com/cyberbotics/webots/R2023b/projects/objects/backgrounds/protos/TexturedBackground.proto"
EXTERNPROTO "https://raw.githubusercontent.com/cyberbotics/webots/R2023b/projects/objects/backgrounds/protos/TexturedBackgroundLight.proto"
EXTERNPROTO "https://raw.githubusercontent.com/cyberbotics/webots/R2023b/projects/objects/floors/protos/RectangleArena.proto"

WorldInfo {
}
Viewpoint {
  orientation 0.33803965107324996 0.41073685502149043 -0.8467729508134577 1.680487805218006
  position -1.6877303227031792 0.8983228154528423 1.7163568784980097
}
TexturedBackground {
}
TexturedBackgroundLight {
}
RectangleArena {
  floorSize 4 4
  floorTileSize 4 4
  floorAppearance Appearance {
    texture ImageTexture {
      url [
        "grille.png"
      ]
    }
    textureTransform TextureTransform {
      scale 1.05 1
      translation -0.97 1
    }
  }
}
Robot {
  translation -1.6859800011139583 -1.3413100000000209 0.03972097932870052
  rotation -4.5157178828191e-08 -4.5157854741085464e-08 0.9999999999999979 1.570811301179434
  children [
    DEF CAM Camera {
      translation 0.1 0 0.03
      rotation 0 1 0 0.523599
      children [
        Shape {
          appearance PBRAppearance {
          }
          geometry Box {
            size 0.01 0.01 0.01
          }
        }
      ]
      width 640
      height 480
    }
    DEF BODY Shape {
      appearance PBRAppearance {
        baseColor 0.917647 0.145098 0.145098
        roughness 1
        metalness 0
      }
      geometry Box {
        size 0.2 0.1 0.05
      }
    }
    DEF WHEEL1 HingeJoint {
      jointParameters HingeJointParameters {
        position -3.7588286372836867e-07
        axis 0 1 0
        anchor 0.05 0.06 0
      }
      device [
        DEF s1 PositionSensor {
          name "s1"
        }
        RotationalMotor {
          name "wheel1"
        }
      ]
      endPoint Solid {
        translation 0.05 0.06 0
        rotation 0.9999999999999647 -1.8798239579819374e-07 1.8798308630135388e-07 1.5707999999999938
        children [
          DEF WHEEL Shape {
            appearance PBRAppearance {
              baseColor 0.305882 0.898039 0.25098
              roughness 1
              metalness 0
            }
            geometry Cylinder {
              height 0.02
              radius 0.04
              subdivision 24
            }
          }
        ]
        boundingObject USE WHEEL
        physics Physics {
        }
        linearVelocity -8.740040736303772e-12 4.961467619633111e-17 3.0126612713701026e-08
        angularVelocity 4.262979148444345e-16 -2.1850512598903825e-10 -1.418786976131638e-15
      }
    }
    DEF WHEEL2 HingeJoint {
      jointParameters HingeJointParameters {
        position 1.409984475337136e-06
        axis 0 1 0
        anchor 0.05 -0.06 0
      }
      device [
        DEF s2 PositionSensor {
          name "s2"
        }
        RotationalMotor {
          name "wheel2"
        }
      ]
      endPoint Solid {
        translation 0.05 -0.06 0
        rotation 0.9999999999995032 7.049864183392623e-07 -7.049890079548263e-07 1.5708000000004738
        children [
          USE WHEEL
        ]
        name "solid(1)"
        boundingObject USE WHEEL
        physics Physics {
        }
        linearVelocity -8.740530673664391e-12 -1.0689522352134255e-16 3.015117465324548e-08
        angularVelocity 1.1380322980973279e-15 -2.1850257747671368e-10 -1.0566258758115686e-15
      }
    }
    DEF WHEEL3 HingeJoint {
      jointParameters HingeJointParameters {
        position -3.785680643853833e-07
        axis 0 1 0
        anchor -0.05 0.06 0
      }
      device [
        DEF s3 PositionSensor {
          name "s3"
        }
        RotationalMotor {
          name "wheel3"
        }
      ]
      endPoint Solid {
        translation -0.05 0.06 0
        rotation 0.9999999999999641 -1.894141580343598e-07 1.8941485382243183e-07 1.5708000000000186
        children [
          USE WHEEL
        ]
        name "solid(2)"
        boundingObject USE WHEEL
        physics Physics {
        }
        linearVelocity -8.740243818857512e-12 5.485234353396464e-17 3.012661193622963e-08
        angularVelocity 2.29775630289831e-16 -2.185025774651813e-10 -7.439007919621769e-16
      }
    }
    DEF WHEEL4 HingeJoint {
      jointParameters HingeJointParameters {
        position 1.4108057488579017e-06
        axis 0 1 0
        anchor -0.05 -0.06 0
      }
      device [
        DEF s4 PositionSensor {
          name "s4"
        }
        RotationalMotor {
          name "wheel4"
        }
      ]
      endPoint Solid {
        translation -0.05 -0.06 0
        rotation 0.9999999999995024 7.053970532380228e-07 -7.053996446367043e-07 1.570800000000476
        children [
          USE WHEEL
        ]
        name "solid(3)"
        boundingObject USE WHEEL
        physics Physics {
        }
        linearVelocity -8.740271088674153e-12 -9.088733001097241e-17 3.015117415849684e-08
        angularVelocity 5.376599392662112e-16 -2.1850767451180727e-10 -8.116385702925953e-16
      }
    }
    DEF DS DistanceSensor {
      translation 0.101146 -2.18955e-05 0
      rotation 0 0 -1 0.0382006
      children [
        Shape {
          appearance PBRAppearance {
            baseColor 0.184314 0.596078 0.847059
            roughness 1
            metalness 0
          }
          geometry Box {
            size 0.01 0.01 0.01
          }
        }
      ]
      name "ds"
    }
  ]
  boundingObject USE BODY
  physics Physics {
    density -1
    mass 1
  }
  controller "main"
  linearVelocity -8.738707196227701e-12 -2.3345186333085595e-17 -2.2156922341310102e-10
  angularVelocity -1.0764579484432742e-15 -2.1845181647970506e-10 -3.4382592024231745e-15
}
